Workbook

Sheet Summary
A1: NSW RWC Legacy Program - data compiled from all project files
A2: Compiled 24 Sep 2026. Highlighting: Facilities & Equipment and Programs & Workforce.
A4: Legend
A5: F&E | B5: Facilities & Equipment (Pillar 1) data
A6: P&W | B6: Programs & Workforce (Pillar 3) data
A7: Both | B7: Programs & Workforce item that also involves equipment/facilities
A8: INC | B8: Inclusion (Pillar 4) data - women & girls, First Nations, Pasifika, All Abilities, Pride, safeguarding
A9: Related | B9: Sits in another pillar but has a facilities, equipment or workforce component
A11: Key figures
A12: Dashboard 3-year budget, all rows ($) | B12: ='Dashboard (all rows)'!I28 -> 3537000 | C12: Sum of year 1-3 budgets on the Dashboard sheet
A13: Dashboard 3-year budget, Programs & Workforce ($) | B13: ='Dashboard (all rows)'!I29 -> 450000 | C13: MO Manager + Workforce Recruitment & Development + Workforce Leadership
A14: Dashboard 3-year budget, Facilities & Equipment ($) | B14: ='Dashboard (all rows)'!I30 -> 0 | C14: No F&E lines on the dashboard
A15: Referee department identified spend ($) | B15: ='MO & Volunteer budgets'!G8 -> 22087.5 | C15: MOs sheet
A16: Volunteer Rewards & Recognition program ($) | B16: ='MO & Volunteer budgets'!C17 -> 7500 | C16: Volunteers sheet
A17: Total Legacy funding | B17: $10M | C17: Annual Report: $5M to NSWRU; rest to clubs, zones, affiliates for infrastructure, participation & equipment grants
A18: F&E targets | B18: 20 facilities; 2 major upgrades; >20 clubs equipment | C18: Project Plan
A19: Coach & MO accreditation growth 2025 | B19: +18% YoY | C19: Annual Report 2025
A20: Dashboard 3-year budget, Inclusion ($) | B20: =SUMIFS('Dashboard (all rows)'!I3:I27,'Dashboard (all rows)'!C3:C27,"P4 Inclusion") -> 1167000 | C20: Female, First Nations, Pasifika, Integrity, All Abilities, Pride
A24: Sheets
A25: Benchmark | B25: How 12 other sports organisations measure performance + recommended measures
A26: Impact Analysis | B26: Spend by area, progress vs targets, benchmark values, insights
A27: Legacy Grants R1 2025-26 | B27: All 38 Round 1 grants with locations
A28: Dashboard (all rows) | B28: Every row of the RWC Dashboard with budgets split by year
A29: MO & Volunteer budgets | B29: Referee department and volunteer program budgets
A30: Program Logic | B30: Needs, evidence, activities, outputs and outcomes for each component
A31: Targets & Baselines | B31: Every KPI with baseline and target
A32: Annual Report 2025 | B32: Participation, workforce, facility and financial data
A33: Strategic Plan | B33: NSWRU 2025-27 priorities
A34: Evaluation Guidance | B34: Treasury TPG22-22 and Evidence Bank requirements & data
A35: Gaps & Issues | B35: Missing data and inconsistencies between files

Sheet Impact Analysis
A1: Impact Analysis - where the money goes and early evidence of economic & social impact
A2: Program is ~1 year into a 3-year cycle (2025-2028). Figures below are spending, outputs and early outcome indicators; no monetised impact evaluation exists yet. Green text = linked from other tabs; blue = hardcoded input with source.
A4: A. Spending by area (known allocations)
A5: Area | B5: NSWRU dashboard, 3 yrs ($) | C5: R1 grants 2025-26 ($) | D5: Total known ($) | E5: Share of total | G5: What it buys
A6: Facilities & Equipment | B6: =SUMIFS('Dashboard (all rows)'!I3:I27,'Dashboard (all rows)'!C3:C27,"P1*") -> 0 | C6: =SUMIFS('Legacy Grants R1 2025-26'!I3:I40,'Legacy Grants R1 2025-26'!A3:A40,"F&E") -> 1851050 | D6: =B6+C6 -> 1851050 | E6: =D6/$D$11 -> 0.32548795 | G6: 18 facility projects: lighting, changerooms, drainage. Plus Round 2 (outcomes Nov 2026) and 2 priority facilities (amounts not published)
A7: Programs & Workforce | B7: =SUMIFS('Dashboard (all rows)'!I3:I27,'Dashboard (all rows)'!C3:C27,"P3*") -> 450000 | C7: =SUMIFS('Legacy Grants R1 2025-26'!I3:I40,'Legacy Grants R1 2025-26'!A3:A40,"P&W") -> 223372 | D7: =B7+C7 -> 673372 | E7: =D7/$D$11 -> 0.11840549 | G7: MO Manager, workforce recruitment & leadership, referee/coach programs, competitions
A8: Inclusion | B8: =SUMIFS('Dashboard (all rows)'!I3:I27,'Dashboard (all rows)'!C3:C27,"P4*") -> 1167000 | C8: =SUMIFS('Legacy Grants R1 2025-26'!I3:I40,'Legacy Grants R1 2025-26'!A3:A40,"INC") -> 75578 | D8: =B8+C8 -> 1242578 | E8: =D8/$D$11 -> 0.21849446 | G8: Female, First Nations, Pasifika, integrity, All Abilities, Pride staff & programs; girls/inclusive grants
A9: Priority Regions (W. Sydney, Hunter) | B9: =SUMIFS('Dashboard (all rows)'!I3:I27,'Dashboard (all rows)'!C3:C27,"P2*") -> 1220000 | C9: 0 | D9: =B9+C9 -> 1220000 | E9: =D9/$D$11 -> 0.21452435 | G9: W. Sydney GM, CDM, DO, comps, academy; Hunter R4G
A10: RWC Activation + PM/M&E | B10: =SUMIFS('Dashboard (all rows)'!I3:I27,'Dashboard (all rows)'!C3:C27,"P5*")+SUMIFS('Dashboard (all rows)'!I3:I27,'Dashboard (all rows)'!C3:C27,"PM*") -> 700000 | C10: 0 | D10: =B10+C10 -> 700000 | E10: =D10/$D$11 -> 0.12308774 | G10: Event hubs ($370k in 2027), M&E, project management
A11: Total known | B11: =SUM(B6:B10) -> 3537000 | C11: =SUM(C6:C10) -> 2150000 | D11: =SUM(D6:D10) -> 5687000 | E11: =SUM(E6:E10) -> 1
A12: Staff salaries on dashboard (code "RWC Wages") | B12: =SUMIFS('Dashboard (all rows)'!I3:I27,'Dashboard (all rows)'!L3:L27,"RWC Wages") -> 1297000 | E12: =B12/B11 -> 0.36669494 | G12: 8 funded roles. Salaries end with the grant in 2028 - key sustainability risk
A13: Holroyd co-investment leverage (grant vs project cost) | B13: 150000 | D13: 561000 | E13: =D13/B13 -> 3.74 | G13: Every $1 of Legacy grant unlocked ~$3.74 of total project spend (Cumberland Council). Round 2 needs >=25% co-contribution
A14: Round 1 facility $ outside Greater Sydney | B14: =SUMIFS('Legacy Grants R1 2025-26'!I3:I40,'Legacy Grants R1 2025-26'!A3:A40,"F&E")-SUMIFS('Legacy Grants R1 2025-26'!I3:I40,'Legacy Grants R1 2025-26'!A3:A40,"F&E",'Legacy Grants R1 2025-26'!H3:H40,"Sydney*")-SUMIFS('Legacy Grants R1 2025-26'!I3:I40,'Legacy Grants R1 2025-26'!A3:A40,"F&E",'Legacy Grants R1 2025-26'!H3:H40,"Western Sydney") -> 1264258 | E14: =B14/SUMIFS('Legacy Grants R1 2025-26'!I3:I40,'Legacy Grants R1 2025-26'!A3:A40,"F&E") -> 0.68299506 | G14: Regional share of facility grants
A16: B. Early outcome indicators (2025) vs 3-year targets
A17: Indicator | B17: Baseline | C17: 3-yr target growth | D17: Required growth p.a. | E17: 2025 actual growth | F17: On track? | G17: Source / note
A18: Accredited coaches | B18: 3514 | C18: 0.5 | D18: =(1+C18)^(1/3)-1 -> 0.14471424 | E18: 0.18 | F18: =IF(E18="","No data",IF(E18>=D18,"Ahead",IF(E18>=0.8*D18,"Close","Behind"))) -> Ahead | G18: Annual Report: +18% YoY. Baseline year assumed = 2024
A19: Accredited match officials | B19: 1281 | C19: 0.75 | D19: =(1+C19)^(1/3)-1 -> 0.20507113 | E19: 0.18 | F19: =IF(E19="","No data",IF(E19>=D19,"Ahead",IF(E19>=0.8*D19,"Close","Behind"))) -> Close | G19: Annual Report: +18% YoY. Needs ~20.5% p.a.
A20: Female participation | B20: 7917 | C20: 0.5 | D20: =(1+C20)^(1/3)-1 -> 0.14471424 | E20: 0.06 | F20: =IF(E20="","No data",IF(E20>=D20,"Ahead",IF(E20>=0.8*D20,"Close","Behind"))) -> Behind | G20: Annual Report: women's game +6%
A21: Female match officials | B21: 106 | C21: 2 | D21: =(1+C21)^(1/3)-1 -> 0.44224957 | F21: =IF(E21="","No data",IF(E21>=D21,"Ahead",IF(E21>=0.8*D21,"Close","Behind"))) -> No data | G21: No 2025 figure published
A22: Female coaches | B22: 192 | C22: 1.5 | D22: =(1+C22)^(1/3)-1 -> 0.35720881 | F22: =IF(E22="","No data",IF(E22>=D22,"Ahead",IF(E22>=0.8*D22,"Close","Behind"))) -> No data | G22: No 2025 figure published
A23: Western Sydney participation (annual target 7.5%) | B23: 6127 | D23: 0.075 | E23: 0.09 | F23: =IF(E23="","No data",IF(E23>=D23,"Ahead",IF(E23>=0.8*D23,"Close","Behind"))) -> Ahead | G23: Annual Report: +9% in 2025; target is +7.5% p.a.
A24: XV club players (NSWRU KPI: +25% participants by 2027) | B24: 38244 | C24: 0.25 | D24: =(1+C24)^(1/2)-1 -> 0.11803399 | E24: 0.011 | F24: =IF(E24="","No data",IF(E24>=D24,"Ahead",IF(E24>=0.8*D24,"Close","Behind"))) -> Behind | G24: Annual Report: +1.1% to 38,244
A27: C. Benchmarks for putting a $ value on impact
A28: Benchmark | B28: Value | C28: Unit | G28: Source / how to use
A29: Value of sport volunteering (Australia) | B29: 3000000000 | C29: $/yr | G29: ASC Clearinghouse: 158M hrs/yr ~ 90,000 FTE ~ $3B. Use hourly value x rugby volunteer hours
A30: Implied value per volunteer hour | B30: =B29/158000000 -> 18.987342 | C30: $/hr | G30: Derived from row above
A31: Social value per female rugby player | B31: 3132 | C31: US$/yr | G31: World Rugby & Portas (2023) SROI
A32: Social value per male rugby player | B32: 1900 | C32: US$/yr | G32: World Rugby & Portas (2023) SROI
A33: Community sport infrastructure value (Victoria) | B33: 7040000000 | C33: $/yr | G33: KPMG for Sport & Recreation Victoria (2021): social $2.6B, health $2.3B, economic $2.1B, 13,000+ FTE
A34: Community sport & recreation value (NSW) | B34: 34700000000 | C34: $/yr | G34: UTS for Sport NSW, "Beyond the Game" (Feb 2026): $4,039 per resident; 2M participants, 900k volunteers
A35: Rugby for Good benefit-cost ratio | B35: 3 | C35: x | G35: Positive Rugby Foundation Balmoral Report (cited in Program Logic): >3:1
A36: Clontarf (sport-based First Nations program) BCR | B36: 1.01 | C36: x | G36: NSW Treasury Evidence Bank 2026 - conservative, justice & health benefits not counted
A37: Sport return per $1 (Australia) | B37: 7 | C37: x | G37: BCG (2017) via ASC Clearinghouse
A39: D. Illustrative calculation - social value of 2025 female growth (not an evaluation result)
A40: Female XV club players 2025 | B40: 6160 | G40: Annual Report key stats
A41: Women's game growth 2025 | B41: 0.06 | G41: Annual Report
A42: Implied additional female players | B42: =B40-B40/(1+B41) -> 348.67925
A43: Annual social value of those players (US$) | B43: =B42*B31 -> 1092063.4 | G43: x World Rugby per-female-player value
A44: Share of 3-yr Inclusion spend (dashboard) | B44: =B43/B8 -> 0.93578697 | G44: Rough: 1 year of value vs 3-yr budget; ignores attribution & FX
A46: E. Insights
...

Sheet Benchmark
A1: How other sports organisations and legacy programs measure performance and impact. Researched 24 Sep 2026.
A2: Organisation | B2: Type | C2: Program / scope | D2: Framework / method | E2: Outcomes measured | F2: Data sources | G2: Cadence | H2: Headline result | I2: Lesson for NSW RWC Legacy | J2: Source
A3: Sport England | B3: National sport agency (UK) | C3: Social & economic value of community sport | D3: SROI model (Sheffield Hallam); values wellbeing (WELLBYs), health, social/community and economic outcomes | E3: Health savings; wellbeing; volunteering; GVA | F3: Active Lives survey (national participation & volunteering); health evidence base | G3: Annual (Year 2 update Nov 2025) | H3: £122.9B social value 2023/24; £4.38 per £1 invested | I3: Use a standard, repeatable SROI model on population survey data; report one ratio each year | J3: https://www.sportengland.org/research-and-data/research/social-value-and-return-investment-sport-and-physical-activity
A4: Scottish Rugby | B4: National rugby union | C4: Grassroots rugby SROI | D4: SROI by Substance; 3 pillars: Social, Health & Wellbeing, Economic | E4: Volunteer value (£31M); juvenile crime reduction; depression/anxiety/chronic disease; facility use (416 pitches) | F4: Survey of 1,600+ players, parents, volunteers, MOs; 60%+ of clubs; club spending & facility data | G4: One-off with club case studies | H4: SROI 7.71:1; £159.16M a year (Health £103.3M, Social £41.2M, Economic £13.5M) | I4: Closest peer: a rugby union SROI with club surveys, volunteer valuation and club case studies (e.g. mums returning to rugby) | J4: https://scottishrugby.org/news-and-features/rugby-in-scotland-delivers-8x-return-on-investment/
A5: World Rugby (with Portas) | B5: International federation | C5: Global social value of community rugby | D5: SROI; value per participant split by gender | E5: Health (mental illness -33%, obesity -30%); wellbeing (US$1.9B); education/earnings | F5: Union participation census + literature-based value coefficients | G5: Periodic (2023 update) | H5: US$8.4B; US$3,132 per female / US$1,900 per male player a year | I5: Gives per-player values the NSW program can multiply by new participants, split by gender | J5: https://www.world.rugby/news/885796/new-report-confirms-community-rugby-contributes-us84-billion-in-social-value-as-global-participation-grows
A6: RWC 2019 Japan (World Rugby, EY, Nielsen) | B6: Major event + legacy | C6: Economic impact + Impact Beyond participation legacy | D6: Economic impact study (EY); public sentiment survey (Nielsen); legacy participation tracking via Get Into Rugby | E6: Output, GDP, jobs, visitor spend; new participants, female share, school tag rugby; national pride | F6: Ticketing, visitor surveys, Get Into Rugby registrations across 22 unions | G6: Pre-event targets; post-event report (2020) | H6: £4.3B output; £2.3B GDP; 46,340 jobs; 2.25M new participants (43.1% female); 769k schoolchildren | I6: Track new-participant counts and female share from RWC hubs; separate event economics from community legacy | J6: https://www.world.rugby/news/572269/rwc-2019-delivers-record-economic-social-and-sporting-outcomes-for-japan
A7: Rugby Australia - Impact Beyond 2027/2029 | B7: National rugby union + Federal Govt | C7: A$30M legacy program (part of A$90M) | D7: Target-based national KPIs; detailed metrics "to be shared" as delivery progresses | E7: Participation; women & girls; club programs; coaches & MOs; 15s & 7s growth | F7: Rugby Xplorer registrations (national census) | G7: To 2029 | H7: Targets: 220k+ participants (+38%); women & girls +70%; club programs 8k to 16.5k; coaches & MOs +30% | I7: NSW targets should roll up to these. NSW workforce targets (+50% coaches, +75% MOs) are more ambitious; NSW female target (+50%) is less ambitious | J7: https://www.rugbyworldcup.com/2027/en/news/1045874/impact-beyond-legacy-programme-launched-with-aud-30-million-funding-to-maximise-rugby-world-cups-benefits-across-australia-and-the-pacific
A8: Football Australia - Legacy '23 | B8: National federation + governments | C8: FIFA Women's World Cup 2023 legacy | D8: Pillar plan with pre- and post-tournament reports | E8: Participation; FACILITIES; leadership & development (coaches, referees); tourism; high performance | F8: Registrations; facility audit (national gap) | G8: Pre / post / ongoing reports | H8: 1.7M participants; A$200M federal Play Our Way facility grants; A$2.9B facility gap identified | I8: Pair facility spending with a quantified national facility gap; publish pre/post legacy reports | J8: https://footballaustralia.com.au/legacy23
A9: AFL community football (La Trobe Uni) | B9: Community clubs | C9: Social value of community football clubs | D9: Club-level SROI; mixed methods | E9: Social connectedness; mental health; employment for ages 15-24; personal development; volunteering | F9: 9 clubs; 110 interviews; 1,677 surveys; police & local government input | G9: One-off study | H9: $4.40 social value per $1 spent on a club | I9: Model for measuring club-level impact at facility-grant and seed-funded clubs | J9: https://aflplayers.com.au/article/study-proves-football-returns-value-to-society
A10: Birmingham 2022 Commonwealth Games (UK DCMS) | B10: Government-funded major event | C10: Games & legacy evaluation | D10: Theory-based evaluation with logic model; interim + 1-year-post reports; methodology annex | E10: GVA; jobs (FTE years); social value; FDI; legacy fund; venue legacy | F10: Economic modelling, surveys, admin data | G10: Interim (2023), 1-year post (Mar 2024) | H10: £1.2B GVA; 22,380 FTE years; £79.5M social value (£150M+ potential) | I10: Government-grade template: logic model, staged reports, published method annex (matches TPG22-22) | J10: https://www.commonwealthsport.com/news/3959746/evaluation-of-the-birmingham-2022-commonwealth-games-one-year-post-games-evaluations-report-march-2024
A11: RFU England (with 4Global) | B11: National rugby union | C11: Facility investment model | D11: Live demand-based investment model; interactive mapping | E11: Projected club membership; pitch surplus/deficit; population density; site counts | F11: DataHub + RFU membership data | G11: Live / continuous | H11: Weighted prioritisation of facility investment by demand | I11: Use to prioritise and justify Round 2 facility grants and the unnamed Sydney priority site | J11: https://4global.com/case-study/rfu-rugby/
A12: Sport NSW / UTS - Beyond the Game | B12: State peak body | C12: Value of community sport & recreation in NSW | D12: Social, economic & health valuation | E12: Participants; volunteers; social, economic, health benefit | F12: State participation & volunteer data | G12: Feb 2026 | H12: A$34.7B a year; A$4,039 per resident; ~2M participants; 900k volunteers; recommends A$100M a year for facilities | I12: NSW-specific benchmark for the evaluation; same state context | J12: https://www.sportnsw.com.au/news/beyond-the-game-the-value-of-community-sport
A13: Brisbane 2032 - Elevate 2042 | B13: State govt legacy strategy | C13: 20-year Olympic & Paralympic legacy | D13: Vision with themes; implementation & measurement plan still in development | E13: Health & wellbeing; connectivity; environment; economy | F13: TBD | G13: 20 years | H13: No public KPIs yet | I13: Shows the risk of a legacy strategy without early KPIs and baselines | J13: https://www.sport.qld.gov.au/olympic-and-paralympic-games-office/games-legacy
A14: Positive Rugby Foundation (NSW) - Rugby for Good | B14: NSW rugby charity | C14: R4G programs (Tackle Life, Holiday Break, Get Talkin) | D14: Cost-benefit analysis (Balmoral Report) | E14: Mental health; education; youth crime; employment | F14: Program data | G14: One-off | H14: BCR > 3:1 | I14: Existing in-house evidence that can be extended to Hunter R4G and Inclusion programs | J14: Program Logic doc (project file)
A16: Recommended measures for the NSW RWC Legacy framework (drawn from the benchmarks)
A17: Highlight | B17: Area | C17: Measure | D17: Type | E17: Borrowed from | F17: Data source / tool
A18: F&E | B18: Facilities & Equipment | C18: Participation growth at funded sites vs matched unfunded sites | D18: Outcome | E18: AFL/La Trobe club method; Birmingham | F18: Rugby Xplorer by venue
A19: F&E | B19: Facilities & Equipment | C19: Usage hours, night-training capacity (lighting), matches lost to weather | D19: Output / outcome | E19: RFU/4Global; Scottish Rugby (pitch use) | F19: Club & council booking data; RA audit
A20: F&E | B20: Facilities & Equipment | C20: Pitch/changeroom surplus or deficit vs demand, by LGA | D20: Need / prioritisation | E20: RFU/4Global; Football Australia facility gap | F20: RA National Facility Audit + demand model
A21: F&E | B21: Facilities & Equipment | C21: Co-investment leverage and construction jobs | D21: Economic | E21: Birmingham (GVA, FTE years) | F21: Grant data; NSW Treasury employment calculator
A22: P&W | B22: Programs & Workforce | C22: Accredited coaches & MOs; player ratios; workforce churn | D22: Output / outcome | E22: Rugby Australia Impact Beyond (+30%) | F22: Rugby Xplorer / RA LMS
A23: P&W | B23: Programs & Workforce | C23: Volunteer hours x hourly value | D23: Economic / social | E23: Scottish Rugby (£31M volunteer value); Sport England | F23: Volunteer survey; ASC value (~$19/hr)
A24: P&W | B24: Programs & Workforce | C24: Participant & volunteer wellbeing (life satisfaction) | D24: Social | E24: Sport England WELLBY; Scottish Rugby | F24: End-of-season survey with a wellbeing question
A25: INC | B25: Inclusion | C25: Female share of new participants; female, First Nations & Pasifika coaches/MOs/board members | D25: Outcome / equity | E25: RWC 2019 (43.1% female); RA Impact Beyond (+70%) | F25: Rugby Xplorer demographic fields
A26: INC | B26: Inclusion | C26: Social value per new participant by gender | D26: Social (monetised) | E26: World Rugby/Portas | F26: New participants x US$3,132 / US$1,900
A27: INC | B27: Inclusion | C27: Program outcomes: education, employment, mental health | D27: Social | E27: Rugby for Good BCR; Clontarf evaluation | F27: Program surveys; case studies
B28: Whole program | C28: Overall SROI / BCR with 2025 baseline and 2028 follow-up | D28: Economic & social | E28: Scottish Rugby; Sport England; Birmingham | F28: TPG22-22; Treasury Outcomes Values Database
B29: Whole program | C29: RWC hub new participants and conversion to club registration | D29: Legacy | E29: RWC 2019 Impact Beyond | F29: Hub registrations matched to Rugby Xplorer

Sheet Legacy Grants R1 2025-26
A1: Source: NSW Office of Sport, "NSW Rugby World Cup Legacy Program recipients 2025-26" (sport.nsw.gov.au). Category 1 = infrastructure ($25k-$150k); Category 2 = participation programs ($5k-$20k). Glen Innes and Temora locations appear swapped on the source page; corrected here and flagged.
A2: Highlight | B2: Category | C2: Recipient | D2: Project | E2: Upgrade / program type | F2: Suburb / town | G2: LGA | H2: Region | I2: Grant ($)
A3: F&E | B3: 1 | C3: Coffs Harbour Snappers Rugby Union Club | D3: Changeroom upgrades - Coffs Rugby Park | E3: Changerooms (inclusive/accessible) | F3: Toormina | G3: Coffs Harbour City Council | H3: Mid North Coast | I3: 112348
A4: F&E | B4: 1 | C4: Coonamble Shire Council | D4: Gulargambone Sportsground lighting and changeroom upgrades | E4: Lighting + changerooms | F4: Gulargambone | G4: Coonamble Shire Council | H4: Western NSW | I4: 135200
A5: F&E | B5: 1 | C5: Cumberland Council | D5: Holroyd Sportsgrounds female-friendly facilities (total project $561,000) | E5: Female-friendly changerooms | F5: Holroyd | G5: Cumberland Council | H5: Western Sydney | I5: 150000
A6: F&E | B6: 1 | C6: Emus Rugby Club Limited | D6: Endeavour Oval Field 2 LED lighting upgrade | E6: Lighting | F6: Orange | G6: Orange City Council | H6: Central West | I6: 87628
A7: F&E | B7: 1 | C7: Glen Innes Elks Rugby Union Football Club | D7: Irrigation at Glen Innes Rugby Park | E7: Drainage / irrigation | F7: Glen Innes (listed as Temora) | G7: Glen Innes Severn (listed as Temora Shire) | H7: New England | I7: 108626
A8: F&E | B8: 1 | C8: Goulburn Rugby Union Football Club | D8: Change room upgrades | E8: Changerooms | F8: Goulburn | G8: Goulburn Mulwaree Council | H8: Southern Tablelands | I8: 49025
A9: F&E | B9: 1 | C9: Inverell Rugby Club | D9: Playing Safe Under Lights | E9: Lighting | F9: Inverell | G9: Inverell Shire Council | H9: New England | I9: 150000
A10: F&E | B10: 1 | C10: Manly Rugby Football Club | D10: Keirle Park refurbishment incl. change rooms | E10: Changerooms | F10: Manly | G10: Northern Beaches Council | H10: Sydney - Northern Beaches | I10: 81387
A11: F&E | B11: 1 | C11: Mid-Western Regional Council | D11: Glen Willow Regional Sporting Complex rugby PA system upgrade | E11: PA / amenity | F11: Mudgee (Putta Bucca) | G11: Mid-Western Regional Council | H11: Central West | I11: 150000
A12: F&E | B12: 1 | C12: Muswellbrook Shire Council | D12: Highbrook Park facility upgrades | E12: Amenities | F12: Muswellbrook | G12: Muswellbrook Shire Council | H12: Hunter | I12: 103565
A13: F&E | B13: 1 | C13: Orange City Rugby Club Inc | D13: New amenities building and spectator awning | E13: Amenities + shade | F13: Orange | G13: Orange City Council | H13: Central West | I13: 150000
A14: F&E | B14: 1 | C14: Port Macquarie-Hastings Council | D14: Stuart Park Regional Sporting Precinct Field 5 subsurface drainage | E14: Drainage | F14: Port Macquarie | G14: Port Macquarie-Hastings Council | H14: Mid North Coast | I14: 105553
... A40: P&W | B40: 2 | C40: Yamba Buccaneers Rugby Club | D40: Clarence Valley Rugby 7s schools competition | E40: Competition | F40: Yamba | G40: Clarence Valley Council | H40: Northern Rivers | I40: 15000
G41: Projects
F42: Category 1 - Facilities total | G42: =COUNTIFS(B3:B40,"1") -> 18 | I42: =SUMIFS(I3:I40,B3:B40,"1") -> 1851050
F43: Category 2 - Programs total | G43: =COUNTIFS(B3:B40,"2") -> 20 | I43: =SUMIFS(I3:I40,B3:B40,"2") -> 298950
F44: Round 1 total | G44: =COUNTA(C3:C40) -> 38 | I44: =SUM(I3:I40) -> 2150000
A46: Facilities budget elsewhere in the $10M (from project files):
A47: - Round 2 (2026/27): up to a further ~$2.15M; Category 1 closed 14 Aug 2026, outcomes from Nov 2026; 25% co-contribution; works Jan 2027 - Jan 2029.
A48: - Targeted priority infrastructure: Connolly Park, Wagga Wagga (ACT & Southern NSW Rugby Union + RA) and one Sydney priority facility (NSWRU + RA; venue not named). No dollar amount or confirmation found publicly.
A49: - Equipment grants (e.g. scrum machines ~$11k) are planned in the Project Plan; no separate equipment recipients are published, and Round 1 folded equipment into Category 2.
A50: - Conolly Park (Wagga) is getting changeroom & plumbing work from a separate $134k ClubGRANTS/council project (Wagga City Council, May 2026) - not RWC Legacy money.

Sheet Dashboard (all rows)
A1: Source: RWC Dashboard 010926 2.xlsx, sheet "Dashboard" (every row, A2:H27). Year budgets split from the "3 year Budget" text column. Pillar mapping from Project Plan. NOTE: the dashboard has NO Pillar 1 Facilities & Equipment initiatives.
A2: Highlight | B2: Why highlighted | C2: Project Plan pillar | D2: Initiative | E2: Key activities | F2: Year 1 budget ($) | G2: Year 2 budget ($) | H2: Year 3 budget ($) | I2: 3-year total ($) | J2: Budget items | K2: NSWRU initiatives | L2: Code | M2: Due / status | N2: Performance measures
C3: P2 Priority Regions | D3: Western Sydney GM | E3: * Appoint Head of Western Sydney * Manage Strategic and operational diretion for Western Sydney * Manage WS Academy * Work with Club Developemnt Manager to lead club strategic direction * Launch Western Sydney Rugby Alliance | F3: 65000 | G3: 65000 | H3: 65000 | I3: =IF(COUNT(F3:H3)=0,"",SUM(F3:H3)) -> 195000 | J3: WS GM Salary | K3: Appoint Head of WS | L3: RWC Wages | M3: In place | N3: Western Sydney Rugby alliance that meets 3 x annually New schools’ competition incl. Western Sydney Waratah Shield Division, U16 competition, and primary school competition for boys and girls and foster links between schools and local clubs Launch Western Sydney academy – 30 males and 30 females in the program per season Increase Western Sydney funding through Rugby for Good hub – source $125k annually
A4: Related | B4: Workforce: club development training & education for administrators | C4: P2 Priority Regions | D4: Western Sydney Club Development Mgr | E4: * Appoint Western Sydney Club Development Manager * Increased Club Development support to improve existing clubs and develop new clubs where required. * Support clubs to reach governance standards. * Support clubs with their attainment of 40:40:20 Governance model * Deliver yearly Club Health Check for each W. Syd club * Deliver yearly Club Development workshops * Deliver Action Plans for each club * Deliver appropriate training, education and assistance | F4: 55000 | G4: 65000 | H4: 65000 | I4: =IF(COUNT(F4:H4)=0,"",SUM(F4:H4)) -> 185000 | J4: WS CDM Salary | K4: Appoint WS CDM | L4: RWC Wages | M4: In place | N4: Ensure all clubs in Western Sydney reach Developing standards in the RA Club Standards program and are all legally compliant organisations Club Development Manager to meet all clubs in Western Sydney twice annually Each Western Sydney club to complete the RA Club Health Check annually Each club to receive a tailored Club Action Plan Drive increase in gender balanced club boards (40:40:20) - 40% of clubs currently meet this ratio Reduce participant churn by 1% per year - baseline 48.9% in Western Sydney
A5: Related | B5: Workforce: 3 coaching courses p.a.; recruit/retain coaches & match officials | C5: P2 Priority Regions | D5: Western Sydney DO | E5: * Appoint Western Sydney Development Officer * Deliver Western Sydney Schools programs * Connect Western Sydney schools with local clubs * Attend club training sessions * Deliver coaching course in Western Sydney * Support junior clubs with recruitment and retention of players, coaches and match officials * Convert exposure/sampling opportunities in gala days and programs into regular club rugby participants | F5: 45000 | G5: 45000 | H5: 45000 | I5: =IF(COUNT(F5:H5)=0,"",SUM(F5:H5)) -> 135000 | J5: WS DO Salary | K5: Appoint WS DO | L5: RWC Wages | M5: Currently being recuited. Co-funding from Eastwood | N5: Increase overall participation by 7.5% per annum – schools, clubs, gala days, tournaments Deliver 3 x coaching courses per annum Attend club training sessions 2 x per annum Reduce participant churn by 1% per year - baseline 48.9%
A6: Related | B6: Competition seed-funding (P&W activity type) + equipment items (uniforms) | C6: P2 Priority Regions | D6: Western Syd Comps | E6: * Seed-fund new, and grow existing competitions in Western Sydney across clubs and schools in both contact and non-contact formats * Develop new Schools competition including Western Sydney Waratah Shield Division, U16 and Primary school competition for boys and girls | F6: 85000 | G6: 75000 | H6: 65000 | I6: =IF(COUNT(F6:H6)=0,"",SUM(F6:H6)) -> 225000 | J6: Casual Dev Staff Uniforms Team travel Medic Referees | K6: New Western Sydney High School Competition (feed into Junior Clubs) | L6: RWC WS Comps | M6: 6 x Schools locked in DOs in schools | N6: As above
A7: Related | B7: Equipment/facility items: uniforms, field hire; coach/S&C/physio hire | C7: P2 Priority Regions | D7: Western Syd Rugby Development Centre | E7: * Develop a Western Sydney academy to assist pathway development * Identify talent in Western Sydney to join Academy | F7: 75000 | G7: 75000 | H7: 75000 | I7: =IF(COUNT(F7:H7)=0,"",SUM(F7:H7)) -> 225000 | J7: Uniforms Field hire Hire - coach, S&C, Physio | K7: Regional Academy commenced 16 weeks Nov-March | L7: RWC WS RDC | M7: Regional Academy implmetned in Western Sydney | N7: As above
A8: Both | B8: P&W core. Also equipment: "Increased access to equipment and filming resources for MOs" | C8: P3 Programs & Workforce | D8: Match Official Manager | E8: * Appoint NSW Match Official Manager * Lead NSW MO strategy and operational planning * Deliver Match Official workshops and mentoring programs * Implement MO development program * Deliver on recruitment campaigns focused on female referees * Promote improved sideline behaviour through ongoing education and sanction process * Targeted recruitment focusing on recently retired players * Club/Hub based programs to bring MO’s to younger age groups * Increased access to equipment and filming resources for MO’s | F8: 55000 | G8: 55000 | H8: 55000 | I8: =IF(COUNT(F8:H8)=0,"",SUM(F8:H8)) -> 165000 | J8: * MO Manager Salary | K8: Appoint MO Manager | L8: RWC Wages | M8: In place | N8: Each game in NSW to have an appointed and accredited Match Official Match Officials to Player ratio of 30:1 – baseline 56:1 Improve sideline and player behaviour with 25% reduction in Match Official abuse cases – baseline 73 cases Grow accredited Match Officials by 75% - baseline of 1,281 match officials Increase number of referees from underrepresented groups; female, Pasifika and First Nations Match Officials – baseline 106 females, 80 Pasifika and 13 First Nations Match Officials 200% growth in female match officials – baseline of 106 accredited female Match Officials
C9: P2 Priority Regions | D9: Hunter/Newcastle RFG Manager | E9: * Appoint Hunter Rugby for Good General Manager * Lead the Rugby for Good program in the Hunter * Secure additional funding to deliver Rugby for Good activity in the -Hunter region including Rucky Tackle Life, Rugby for Good Mental Health Programs, Our Turn, Your Time Women’s program | F9: 50000 | G9: 60000 | H9: 60000 | I9: =IF(COUNT(F9:H9)=0,"",SUM(F9:H9)) -> 170000 | J9: Hunter/Newcastle RFG Manager Salary | K9: Appoint Hunter/Newcastle RFG Manager | L9: RWC Wages | M9: In place | N9: Increase participation by 7.5% annually across all metrics – clubs, schools, coaches, match officials and administrators – baseline 3,290 Source additional revenue opportunities via Rugby for Good programs – source >$100k annually Ensure all clubs in the Hunter reach Bronze/Developing standards in the RA Club Standards program and are all legally compliant organisations Each Hunter club to complete the RA Club Health Check annually Each club to receive a tailored Club Action Plan
C10: P2 Priority Regions | D10: Hunter R4G Activities | E10: * Club Development activity in the Hunter * Competition and program support in the Hunter * Deliver programs and provide opportunities that enhance, support and build rugby communities * Complete Club Health audit for Hunter Rugby clubs * Deliver Action Plans for each club | F10: 10000 | G10: 20000 | H10: 55000 | I10: =IF(COUNT(F10:H10)=0,"",SUM(F10:H10)) -> 85000
A11: INC | B11: Inclusion: First Nations Manager | C11: P4 Inclusion | D11: First Nations Manager | E11: * Appoint First Nations Development Officer * Deliver First Nations activity in NSW (see below) | F11: 45000 | G11: 55000 | H11: 55000 | I11: =IF(COUNT(F11:H11)=0,"",SUM(F11:H11)) -> 155000 | J11: First Nations Manager Salary | K11: Appoint First Nations Manager | L11: RWC Wages | M11: In place | N11: Deliver NSWRU Reconciliation Action Plan Deliver 6 x Talent ID workshops annually (North Coast, Central West, Sydney Metro, South Coast, 2 x Southern Inland) Deliver NSW First Nations Development Academy
A12: INC | B12: Inclusion: First Nations talent ID, Academy, RAP; also coach bursaries (workforce) | C12: P4 Inclusion | D12: First Nations Activities | E12: * Host regional and metro talent ID days in NSW to transition talent into high performance pathways. * First Nations Development Academy-Work with Lloyd McDermott Rugby to develop a First Nations Leadership program aligned with U16 boys’ and girls’ programs * First Nations mentoring programs * Bursary places for First Nations coaches * Deliver NSWRU RAP | F12: 80000 | G12: 80000 | H12: 80000 | I12: =IF(COUNT(F12:H12)=0,"",SUM(F12:H12)) -> 240000 | M12: Ella 7s
A13: INC | B13: Inclusion: Pasifika & First Nations leadership; coach bursaries (workforce) | C13: P4 Inclusion | D13: Pasifika & First Nations Leadership Activity | E13: * Leadership and support programs for Pasifika and First Nations people * Work with Lloyd McDermott Rugby to develop a First Nations Leadership program aligned with U16 boys’ and girls’ programs * First Nations mentoring programs * Bursary places for First Nations and Pasifika coaches | F13: 25000 | G13: 25000 | H13: 25000 | I13: =IF(COUNT(F13:H13)=0,"",SUM(F13:H13)) -> 75000 | N13: Launch yearly Pasifika Leadership program with 20+ attendees each year Grow attendance at Pasifika Youth Cup by 50%
A14: INC | B14: Inclusion: Pasifika events & leadership | C14: P4 Inclusion | D14: Pacificia Programs | E14: * Enhance existing and develop new Pasifika events and tournaments for children and adults * Deliver Pasifika Leadership program | F14: 55000 | G14: 45000 | H14: 35000 | I14: =IF(COUNT(F14:H14)=0,"",SUM(F14:H14)) -> 135000
A15: INC | B15: Inclusion: Integrity & Safeguarding Manager | C15: P4 Inclusion | D15: Integrity Manager | E15: * Appoint NSW Integrity & Safeguarding manager | F15: 42000 | G15: 55000 | H15: 55000 | I15: =IF(COUNT(F15:H15)=0,"",SUM(F15:H15)) -> 152000 | K15: Appoint Integrity Manager | L15: RWC Wages | M15: JD compiled. Funding from third parties being finalised to complment existing pot | N15: All Rugby clubs in NSW compliant against RA integrity and safeguarding standards Deliver 6 x yearly safeguarding and integrity workshops
A16: INC | B16: Inclusion: safeguarding audits & training for volunteers/admins (workforce) | C16: P4 Inclusion | D16: Integrity Activities | E16: * Audit of Rugby clubs safeguarding, integrity and data management practices (RA Club Health Check) * Identify priority clubs and areas of support following audit * Provide additional and focused training for staff, volunteers and administrators on dealing with integrity and safeguarding matters * Focus on compliance with National, State and local laws, regulations and policies * Improve supporting technology to track WWCC, training completions and incident reporting via Rugby Xplorer * Supporting materials for clubs to promote best practice e.g. posters, online materials, social media posts, etc. | F16: 20000 | G16: 20000 | H16: 20000 | I16: =IF(COUNT(F16:H16)=0,"",SUM(F16:H16)) -> 60000
A17: INC | B17: Inclusion: Female Participation Officer | C17: P4 Inclusion | D17: Female Participation DO | E17: * Appoint Female Participation Officer in NSW * See below in Female Programs and Support | F17: 40000 | G17: 50000 | H17: 50000 | I17: =IF(COUNT(F17:H17)=0,"",SUM(F17:H17)) -> 140000 | K17: Appoint Female Participation DO | L17: RWC Wages | M17: Casul in place | N17: New Female Programs and Competitions across NSW (see competition seed-funding) 50% growth in female participation – baseline of 7,917 club players, 3,642 event players, 16,803 school participants
A18: INC | B18: Inclusion: female programs; coach & MO programs; MO FOC course + whistles/cards $3,500 (equipment) | C18: P4 Inclusion | D18: Female Programs and Support | E18: * Introductory participation programs * New competitions * Talent/ pathway programs * Coach development and Match Officials programs * Club development and support, increasing the number of women in administration and leadership positions withing NSW rugby. | F18: 40000 | G18: 40000 | H18: 40000 | I18: =IF(COUNT(F18:H18)=0,"",SUM(F18:H18)) -> 120000 | J18: * MO FOC Course + Whistles / Cards $3500
A19: INC | B19: Inclusion: female promotion materials | C19: P4 Inclusion | D19: Female Marketing | E19: *Supporting materials for clubs to promote best practice e.g. posters, online materials, social media posts, etc. | F19: 10000 | G19: 10000 | H19: 10000 | I19: =IF(COUNT(F19:H19)=0,"",SUM(F19:H19)) -> 30000
A20: Both | B20: P&W core. Also equipment: MO cards & whistles for new female refs ($5k) | C20: P3 Programs & Workforce | D20: Workforce Recuitment & Development | E20: * Coach and match official education for underrepresented groups (see female, First Nations and Pasifika activity) * Volunteer recruitment and club development programs * Volunteer rewards and recognition programs and opportunities at the RWC 27 * Workforce recruitment for coaches, match officials and administrators * Sustainable club activity – delivering education, training and assistance | F20: 40000 | G20: 40000 | H20: 25000 | I20: =IF(COUNT(F20:H20)=0,"",SUM(F20:H20)) -> 105000 | J20: * MO Cards and Whistles for all new female refs FOC $5k * MO recruitment social media campaign $1k * MO tickets to Waratahs Games $2k * “The Backbone of Rugby” – NSW Volunteer Rewards & Recognition Program $7,500 | L20: RWC WF Rercruitment | N20: Each game in NSW to have an appointed and accredited Match Official Match Officials to Player ratio of 30:1 – baseline 56:1 Coach to Player ratio of 10:1 – baseline 13:1 Improve sideline and player behaviour with 25% reduction in Match Official abuse cases – baseline 73 cases Grow accredited Match Officials by 75% - baseline of 1,281 match officials Grow accredited coaches by 50% - baseline of 3,514 coaches Deliver yearly workforce conference with Net Promotor Score from attendees > 75 Increase number of referees from underrepresented groups; female, Pasifika and First Nations Match Officials – baseline 106 females, 80 Pasifika and 13 First Nations Match Officials Reduce churn by 1% p.a. in workforce numbers – baseline 39.5%
A21: P&W | B21: P&W core: workforce leadership program + NSW Match Developers Conference | C21: P3 Programs & Workforce | D21: Workforce Leadership | E21: * Deliver yearly workforce leadership program for coaches, match officials and administrators * Support growth and development of underrepresented groups in the workforce including Pasifika communities, First Nations and Females | F21: 60000 | G21: 60000 | H21: 60000 | I21: =IF(COUNT(F21:H21)=0,"",SUM(F21:H21)) -> 180000 | J21: NSW Match Developers Conference $10,500 Club Admin Conference (Oct)
A22: INC | B22: Inclusion: All Abilities programs; uniforms (equipment) | C22: P4 Inclusion | D22: All Abilities | E22: * Enhance existing and develop new partnerships and programs to support people with a disability to engage in Rugby | F22: 15000 | G22: 15000 | H22: 15000 | I22: =IF(COUNT(F22:H22)=0,"",SUM(F22:H22)) -> 45000 | J22: Casual Dev Staff Uniforms Team travel Medic Referees | K22: Support existing programs - Vivability in Bathurst, Menai, Rockdale Casul employment All Abilities Rugby Coord to run progams in speial needs schools to attract other grant funding
A23: INC | B23: Inclusion: Pride programs | C23: P4 Inclusion | D23: Pride | E23: * Enhance existing and develop new partnerships and programs to support and celebrate the Pride community in Rugby | F23: 5000 | G23: 5000 | H23: 5000 | I23: =IF(COUNT(F23:H23)=0,"",SUM(F23:H23)) -> 15000 | K23: Contact Andrew Purchas to determine approapriate way forward
A24: Related | B24: Workforce: MO & coaching programs at RWC hubs | C24: P5 RWC Activation | D24: RWC Post-Event Hubs Delivery & Management | E24: * RWC Event Hubs to provide Rugby opportunities during and immediately post the RWC to capture interest in the sport while it is at its peak. This includes: * Get into Rugby (4–7-year-olds) * Tri Tag Rugby – non-contact version of the game suitable for 7 – 97 years of age * Match Officials programs * Coaching programs | F24: 0 | G24: 30000 | H24: 370000 | I24: =IF(COUNT(F24:H24)=0,"",SUM(F24:H24)) -> 400000 | K24: Social Over 35s RWC Come and Try Days International Tournament | N24: Deliver 20 x RWC Event Hubs during & post RWC with a minimum of 50 participants. Each hub to contain: - Get into Rugby - Tri Tag Rugby - Coach education - Match Official education RWC Event Hubs to be spread across metro & regional NSW to ensure everyone has an opportunity to be involved in the Rugby World Cup.
A25: Related | B25: Equipment: giveaways (e.g. mini rugby balls) | C25: P5 RWC Activation | D25: RWC Post-Event Hub Giveaways | E25: * RWC event activation will also include giveaways to prospective participants at matches and in fan-zones to drive a call to action to participate in the sport. | I25: =IF(COUNT(F25:H25)=0,"",SUM(F25:H25))
C26: PM, M&E | D26: Monitoring & Evaluation | E26: * Implement robust monitoring and evaluation process including key social impact measurables, impact reporting and key outcomes. | F26: 75000 | G26: 30000 | H26: 75000 | I26: =IF(COUNT(F26:H26)=0,"",SUM(F26:H26)) -> 180000
C27: PM, M&E | D27: Project Management | E27: * Overall day-to-day project management and oversight and delivery of the legacy program including, but not limited to: -Lead monitoring & evaluation -Grant submission, variation, reporting, communication -Financial management and oversight -Central point of contact | F27: 40000 | G27: 40000 | H27: 40000 | I27: =IF(COUNT(F27:H27)=0,"",SUM(F27:H27)) -> 120000 | J27: Jason Russell-Jones (RA) appointed to manage | M27: RA Funded to assist with project mgt and aqutial
D28: TOTAL (all rows) | F28: =SUM(F3:F27) -> 1032000 | G28: =SUM(G3:G27) -> 1060000 | H28: =SUM(H3:H27) -> 1445000 | I28: =SUM(I3:I27) -> 3537000
D29: of which P3 Programs & Workforce | F29: =SUMIFS(F3:F27,$C3:$C27,"P3 Programs & Workforce") -> 155000 | G29: =SUMIFS(G3:G27,$C3:$C27,"P3 Programs & Workforce") -> 155000 | H29: =SUMIFS(H3:H27,$C3:$C27,"P3 Programs & Workforce") -> 140000 | I29: =SUMIFS(I3:I27,$C3:$C27,"P3 Programs & Workforce") -> 450000
D30: of which P1 Facilities & Equipment | F30: =SUMIFS(F3:F27,$C3:$C27,"P1*") -> 0 | G30: =SUMIFS(G3:G27,$C3:$C27,"P1*") -> 0 | H30: =SUMIFS(H3:H27,$C3:$C27,"P1*") -> 0 | I30: =SUMIFS(I3:I27,$C3:$C27,"P1*") -> 0

Sheet MO & Volunteer budgets
A1: Source: RWC Dashboard workbook, sheets "MOs" (NSW Rugby RWC Legacy Program - Referee Department) and "Volunteers". All items are Programs & Workforce; equipment items flagged Both.
A2: Highlight | B2: Funding pool | C2: Activity | D2: Outcome | E2: Budget detail | F2: How | G2: Referee spend ($) | H2: Program budget ($) | I2: Note
A3: P&W | B3: Female Program Support | C3: Female Match Officials | D3: 100 x new female MOs | E3: 100 x $20 per participant = $2,000; 100 x cards & whistles x $15 = $1,500 | F3: Target girls schools (esp. Chloe Dalton Cup); Subbies & Shute Shield club courses; recently retired players | G3: 3500 | H3: 40000 | I3: Source text reads "100 x 420.00 per participant = $2000" - likely typo for $20
A4: Both | B4: Workforce Leadership | C4: NSW Match Official Conference | D4: Formal exchange program between MOs and MODs within NSW; develop MOD workforce statewide | E4: 1 night accommodation x 20 = $3,600; return airfares x 12 = $6,000; catering x 60 = $900 | F4: Liaise with affiliates; guest presenters (no cost); promote & report outcomes | G4: 10500 | H4: 60000
A5: Both | B5: Workforce Recruitment | C5: Cards and Whistles (EQUIPMENT) | D5: All new referees equipped to begin refereeing | E5: 250 cards = $962.50; 250 whistles = $4,125 | F5: Distributed to all new referees attending a Referee Ready course | G5: 5087.5 | H5: 40000 | I5: Unit costs: $3.85/card, $16.50/whistle
A6: P&W | B6: Workforce Recruitment | C6: Recruitment video & social media campaign | D6: Increase accredited & registered referees by 10% | E6: Social media boosting | F6: Video and flyers for distribution through the year | G6: 1000 | H6: 40000 | I6: Dashboard target is +75% accredited MOs over program
A7: P&W | B7: Workforce Leadership | C7: Tickets to Waratahs' first home game | D7: Reward and recognise referees | E7: 100 tickets x $20 = $2,000 | F7: Tickets at 'Welcome to 2026' function at Rugby Australia | G7: 2000 | H7: 60000
F8: Total referee spend | G8: =SUM(G3:G7) -> 22087.5
A10: "The Backbone of Rugby" - NSW Volunteer Rewards & Recognition Program (sheet "Volunteers")
A11: Highlight | B11: Investment area | C11: Cost ($) | D11: Purpose
A12: P&W | B12: Content Production | C12: 3200 | D12: Short-form videos, filming days, editing for social-first storytelling
A13: P&W | B13: Design & Digital Assets | C13: 1100 | D13: Program branding, winner tiles, certificates, club share packs
A14: P&W | B14: Rewards & Recognition | C14: 1400 | D14: Monthly recognition packs + end-of-program Honour Roll
A15: P&W | B15: Program Management | C15: 1200 | D15: Nominations, selection, coordination, club communications
A16: P&W | B16: Paid Reach & Contingency | C16: 600 | D16: Strategic social boosts and delivery buffer
B17: Total | C17: =SUM(C12:C16) -> 7500
A19: Sheet "Club Dev Conference" in the source workbook is empty (no data).

Sheet Program Logic
A1: Source: Program Logic - NSW Rugby World Cup Legacy.docx (Office of Sport, June 2025, DRAFT). Text condensed; F&E / P&W content in other pillars shown in CAPITALS.
A2: Highlight | B2: Pillar | C2: Component | D2: Need / problem | E2: Evidence | F2: Activities | G2: Outputs | H2: Short-term outcomes | I2: Medium-term outcomes | J2: Long-term outcomes
A3: F&E | B3: P1 Infrastructure & Equipment | C3: Facilities & Infrastructure | D3: Many facilities below community standards: (1) lack of female facilities; (2) inadequate lighting; (3) poor accessibility for disability/cultural needs; (4) inadequate drainage & irrigation amid extreme weather | E3: RA Infrastructure audit: 31% have female-friendly changerooms; 28% female-friendly referee rooms; 62% adequate lighting; 57% adequate drainage & irrigation; 22% parent change facilities. Poor facilities a top reason females avoid sport (Sport England); 1 in 2 females cite lack of female-friendly facilities (VicHealth); facility quality a leading participation factor (NSW OoS, ASC); CSIRO/BOM project more extreme weather | F3: Infrastructure fund, two streams: open program for (a) female-friendly & accessible facilities, (b) lighting, (c) sustainable practices e.g. drainage & irrigation; priority fund for 2-3 strategic priorities | G3: Launch NSW Rugby Infrastructure fund; # facilities funded (lighting, changerooms, sustainable practices); # matches not impacted by rain; co-investment from councils/partners/clubs; 2 x larger-scale priority facility upgrades | H3: Increased investment in inadequate facilities; successful applicants begin construction | I3: Changing perception of rugby for females; increased female participation; clubs run more programs; fewer weather cancellations; stronger council/school relationships via shared-use agreements; diversified club revenue; greater access for people with disability | J3: Facilities cope with climate change; upgraded clubs become community hubs; increased female & diverse representation; priority facilities host major events e.g. state carnivals
A4: F&E | B4: P1 Infrastructure & Equipment | C4: Major Equipment | D4: Scrum machines, goal posts, defibrillators are crucial but cost-prohibitive; scrum is high-risk for injury | E4: World Rugby on scrum machines for technique; scrummaging a disproportionate share of serious injuries; clubs with modern scrum machines report more confidence & better safety; player safety a leading cause of attrition (RA End of Season survey) | F4: Major equipment grant program for high-cost safety & rugby equipment such as scrum machines | G4: # scrum machines & major equipment distributed; # clubs & schools receiving equipment; level of co-investment | H4: Improved safety ratings; fewer serious injuries | I4: Improved recruitment & retention; better scrummaging technique across NSW | J4: Safer environment; continued reduction in injury rates; growth in contact participation
A5: Both | B5: P3 Programs & Workforce | C5: Competition seed-funding | D5: Participation decline/stagnation esp. youth; start-up barriers (equipment, volunteer burden, logistics, facilities, travel); traditional formats; limited school offerings in regional NSW & W. Sydney; club financial capacity | E5: Stagnation where no paid admin staff (RA census); ASC: modified/social formats attract diverse audiences; Tri Tag, Get into Rugby, U85kg pilots show better recruitment & retention | F5: Seed-funding grants: new/expanded comps (regional, youth, female, inclusion, non-contact); starter kits & EQUIPMENT GRANTS; operational support (technology, MOs, travel, FIELD HIRE); promotion; training for administrators. One-off or staged-decrease funding over 3 years | G5: # competitions supported; # clubs/schools/associations; # new & retained participants; # coaches & MOs; # participants in inclusion groups | H5: More & more diverse participants; more appealing comps (EO season survey); improved local delivery capacity | I5: Higher retention vs pre-2025; growth in registered players; growth in volunteer base | J5: Financially sustainable clubs; rugby a "sport of choice"; improved community engagement
A6: P&W | B6: P3 Programs & Workforce | C6: Workforce Development & Leadership | D6: Declining volunteers & burnout; lack of training; coaches & MOs critical to safety; rising governance/compliance/safeguarding burden; under-representation of women, First Nations, Pasifika | E6: Coaches & MOs have largest impact on participant experience (RA census, ASC); volunteer decline (RA Club Health Check, ASC, National Volunteer Coalition); workforce investment boosts performance & stability (NSW OoS); World Rugby on grassroots workforce | F6: Workforce leadership conference (coaches, MOs, administrators); coach & MO education for under-represented groups; volunteer recruitment & club development; volunteer rewards & recognition incl. RWC 27 opportunities | G6: 1 workforce conference p.a.; # accredited coaches, referees, administrators; Coach:Player <1:10; MO:Player <1:30; RA LMS usage; volunteer retention; diversity growth | H6: More coaches, MOs, administrators; better ratios vs 2025; better player & volunteer satisfaction; fewer integrity/safeguarding issues; fewer blue cards (tackle height education) | I6: Higher workforce retention; better club health scores; stronger competitions | J6: More under-represented people in senior roles; higher participation; rugby leads in volunteer recruitment & support
A7: Both | B7: P3 Programs & Workforce | C7: Match Officials | D7: Not enough MOs or coaches for demand; RA targets Player:MO 30:1 and Player:Coach 10:1; attitude to referees predicts participant experience | E7: RA census NSW: 13:1 players to coaches; 53:1 players to MOs. RA participant satisfaction survey: attitude to MOs/coaches is greatest predictor of experience | F7: MO development program: MO developer program; NSW MO pathway; female referee recruitment; club/hub programs for younger MOs; school MO program; EQUIPMENT & FILMING RESOURCES for MOs; continued coach development pathways | G7: FTE MO resources; MO recruitment; MO:Player 1:30; more under-18 MOs; more female MOs; Player:Coach 1:10 | H7: Better support for MOs & coaches; more courses; more diverse coaches & MOs; improved game safety | I7: More diversity; elevated standards; culture change on respect for officials | J7: Valued, supported MO community; diverse MOs; long-term club sustainability
A8: Related | B8: P2 Priority Regions | C8: Western Sydney | D8: Fast-growing but under-represented in playing numbers; weak club footprint (Penrith, Parramatta struggles; no footprint in Camden, Fairfield, Liverpool); no W. Syd schools competition; high CALD population | E8: RA & Kinetica: 11 WSyd LGAs = ~30% of NSW demand but 11% of players; 75% of demand growth from Blacktown, Cumberland, Liverpool; conversion Fairfield 2.2%, Liverpool 5.9%, Canterbury-Bankstown 6.5% vs NSW 32%; <25% of W. Syd within 10-min drive of a club; >50% overseas-born in Fairfield/Auburn/Parramatta vs 29.3% NSW; some LGAs >70% non-English at home vs 25.2% (2021 Census) | F8: Club development support; W. Syd Academy (specialised coaching, S&C); more school programs; new competitions; new clubs in high-demand low-access areas | G8: Academy launch; # school & club programs; # Get into Rugby hubs; # COACH DEVELOPMENT COURSES; # clubs supported/compliant; participation; # new comps; CALD participants | H8: Governance-compliant clubs; higher retention; more school programs | I8: New clubs in growth corridors; more juniors in pathways; conversion in line with NSW average; more CALD participation | J8: W. Syd = 30% of NSW playing population; every resident within 10-min of a club; rugby a sport of choice
B9: P2 Priority Regions | C9: Hunter (Rugby for Good) | D9: Establish R4G hub in the Hunter to drive social outcomes & growth | E9: Hunter issues: youth crime, mental health & suicide above state average, coal transition (Australia Institute, ABS). R4G BCR >3:1 across Tackle Life, Holiday Break, Get Talkin (Balmoral Report) | F9: Rugby Tackle Life; R4G Mental Health Program; Our Turn, Your Time (adolescent girls) | G9: Launch Hunter R4G hub; # Tackle Life, mental health, Our Turn Your Time, Holiday Camp programs | H9: Participation; resilience; local spend & jobs | I9: Sustainable programs; positive health attitudes; reduced crime; mental-health awareness | J9: Improved health; reduced healthcare costs; fewer mental health issues & suicides
A10: Related | B10: P2 Priority Regions | C10: South Coast & Riverina | D10: Declining youth participation; DECLINING QUALITY OF INFRASTRUCTURE (outdated / not fit for purpose); limited pathways esp. female; youth disengagement; under-serviced First Nations; growing Pasifika | E10: Riverina >30% of state output; aligns with regional investment programs; growing Pasifika population (Invest Regional, NSW Planning, ABS) | F10: FACILITIES INVESTMENT incl. targeted investment in CONNOLLY PARK, WAGGA WAGGA; school programs & regional Get into Rugby hubs (5-17 yrs); First Nations; girls pathways; MATCH OFFICIAL SUPPORT & HUBS; community events tied to facilities | G10: # FACILITIES UPGRADED; participation (youth, women, First Nations); GiR & Tri Tag programs; events; female & pathway programs | H10: More opportunities & participants (players, coaches, MOs); CONFIRMED FACILITY INVESTMENT LOCATIONS; more First Nations & Pasifika | I10: More rep selections; sustainable program; community & economic benefits | J10: Riverina hosts major events (e.g. RWC 29 training base, Super Rugby pre-season); Wagga hosts state carnivals
A11: INC | B11: P4 Inclusion | C11: First Nations & Pasifika | D11: High playing share but under-represented in pathways, leadership, coaching, officiating, administration | E11: Pacific Island heritage 1.3% of Australians (2021), +4.5% p.a.; First Nations 3.4% of NSW; in rugby First Nations 7.5% & Pasifika >11% of players but only 3.8% & 4.2% of non-playing roles | F11: Leadership programs; talent ID days; FN Development Academy; Lloyd McDermott leadership program; Pasifika events; mentoring; BURSARY PLACES FOR FN & PASIFIKA COACHES | G11: Yearly education/leadership opps; # training sessions (coaching, MOs, admin); # bursaries; # pathway programs; 6 FN talent ID days p.a.; FN Academy incl. APPAREL, camps | H11: More FN & Pasifika participants, COACHES AND MOs | I11: More FN in rep pathway; better education & retention; leadership share matches playing share | J11: Better health & social outcomes; more FN Wallabies
A12: INC | B12: P4 Inclusion | C12: Female participation | D12: Females under-represented across players, coaches, MOs | E12: Females = 17.3% of national participation: players 15.3%, COACHES 7.8%, MATCH OFFICIALS 11.5%, volunteers 39.3% | F12: Intro programs; new comps; talent/pathways; COACH & MO PROGRAMS; club development for women in admin & leadership | G12: GiR for females; new Tri Tag & 7s comps; more seed-funding; Rising Star combines; ACCELERATED COACH & MO DEVELOPMENT; club admin support | H12: GiR in schools; 2 new TTR & 7s comps (Oct/Nov 25); more female MOs & coaches; SUBSIDISED COACH & MO COURSES | I12: 4 hub locations; Rising Star combines; accelerated coach program; more coach educators & mentors | J12: Sustainable female comps supported by female coaches & MOs; all boards 40:40:20
A13: INC | B13: P4 Inclusion | C13: Integrity & Safeguarding | D13: Scrutiny on child safety; inconsistent policies; compliance; reputational risk; VOLUNTEER BURDEN (WWCC, reporting, training) | E13: SIA: integrity breaches a leading cause of attrition; Royal Commission: community-level safeguarding training needed; parents rank safety & fun top | F13: Club audits (RA Club Health Check); priority club support; TRAINING FOR STAFF, VOLUNTEERS & ADMINISTRATORS; compliance; technology to track WWCC & training (Rugby Xplorer); materials | G13: # Code of Conduct & Judicial Officer training sessions; # committees with WWCC; # complaints resolved; player & volunteer ratings; Club Health Check ratings | H13: Awareness; WWCC compliance; higher CHC scores; every club has a child safeguarding strategy | I13: Fewer breaches; better player & VOLUNTEER RETENTION; recognised best practice | J13: Market-leading safeguarding; culture of respect
A14: Related | B14: P5 RWC Activation | C14: RWC Event Activation | D14: RWC 27 ends after the season; must capture interest immediately | E14: Interest rises 2-4x during major events, returns to baseline within 6 weeks (Google search data); giveaways build connection & call to action | F14: RWC Event Hubs: Get into Rugby (4-7), Tri Tag (7-97), MO PROGRAMS, COACHING PROGRAMS; GIVEAWAYS (mini rugby balls) at matches & fan zones | G14: 20-30 RWC Event Hubs; giveaways; every new registrant receives a new RUGBY BALL | H14: Emotional connection; more activity around RWC 27 | I14: More participation across playing, COACHING AND MOs | J14: Long-term club sustainability

Sheet Targets & Baselines
A1: Every KPI, baseline and target found across the Project Plan, Dashboard and Program Logic. Values in "~" are simple arithmetic on the stated baseline x target %, added for reference.
A2: Highlight | B2: Area | C2: Measure | D2: Baseline | E2: Target | F2: Source
